<?xml version="1.0"?>
<robot xmlns:xacro="http://www.ros.org/wiki/xacro" name="Elrobot">

<!-- Robot parameters -->
  <xacro:property name="body_length" value="0.3"/>  <!-- meters -->
  <xacro:property name="body_width"  value="0.2"/>
  <xacro:property name="body_height" value="0.01"/>
  <xacro:property name="wheel_radius" value="0.04"/>
  <xacro:property name="wheel_thickness" value="0.03"/>

<!-- Main body -->
  <link name="world"/>
  
  <link name="base_link">
    <visual>
      <geometry>
        <box size="${body_length} ${body_width} ${body_height}"/>
      </geometry>
      <material name="red">
        <color rgba="0.8 0 0 1"/>
      </material>
    </visual>
  </link>

  <joint name="world_to_base" type="fixed">
    <parent link="world"/>
    <child link="base_link"/>
    <origin xyz="0 0 0.05" rpy="0 0 0"/>
  </joint>

  <!-- Wheel macro -->    <!-- macro is like a template -->
  <xacro:macro name="wheel" params="name x y z">
    <link name="${name}">
      <visual>
        <geometry>
          <cylinder radius="${wheel_radius}" length="${wheel_thickness}"/>
        </geometry>
        <material name="black">
          <color rgba="0 0 0 1"/>
        </material>
      </visual>
    </link>

    <joint name="${name}_joint" type="continuous">
      <parent link="base_link"/>
      <child link="${name}"/>
      <origin xyz="${x} ${y} ${z}" rpy="1.57 0 0"/>
      <axis xyz="0 1 0"/>
    </joint>
  </xacro:macro>

  <!-- Add four wheels -->
  <xacro:wheel name="f_l"  x="0.09"  y="0.11" z="0.0"/>
  <xacro:wheel name="f_r" x="0.09"  y="-0.11" z="0.0"/>
  <xacro:wheel name="b_l"   x="-0.09" y="0.11" z="0.0"/>
  <xacro:wheel name="b_r"  x="-0.09" y="-0.11" z="0.0"/>

</robot>